{"timestamp":"2025-08-05T00:38:11.048108","level":"info","event":"DAG bundles loaded: dags-folder, example_dags","logger":"airflow.dag_processing.bundles.manager.DagBundlesManager"}
{"timestamp":"2025-08-05T00:38:11.050772","level":"info","event":"Filling up the DagBag from /opt/airflow/dags/etl_dag.py","logger":"airflow.models.dagbag.DagBag"}
{"timestamp":"2025-08-05T00:38:11.225006Z","level":"info","event":"Task instance is in running state","chan":"stdout","logger":"task"}
{"timestamp":"2025-08-05T00:38:11.227468Z","level":"info","event":" Previous state of the Task instance: TaskInstanceState.QUEUED","chan":"stdout","logger":"task"}
{"timestamp":"2025-08-05T00:38:11.229160Z","level":"info","event":"Current task name:run_python_etl","chan":"stdout","logger":"task"}
{"timestamp":"2025-08-05T00:38:11.230471Z","level":"info","event":"Dag name:s3_to_snowflake_etl","chan":"stdout","logger":"task"}
{"timestamp":"2025-08-05T00:38:11.378222Z","level":"error","event":"python: can't open file '/opt/airflow/python/app.py': [Errno 2] No such file or directory","chan":"stderr","logger":"task"}
{"timestamp":"2025-08-05T00:38:11.390516","level":"error","event":"Task failed with exception","logger":"task","error_detail":[{"exc_type":"CalledProcessError","exc_value":"Command '['python', 'python/app.py']' returned non-zero exit status 2.","exc_notes":[],"syntax_error":null,"is_cause":false,"frames":[{"filename":"/home/airflow/.local/lib/python3.12/site-packages/airflow/sdk/execution_time/task_runner.py","lineno":877,"name":"run"},{"filename":"/home/airflow/.local/lib/python3.12/site-packages/airflow/sdk/execution_time/task_runner.py","lineno":1164,"name":"_execute_task"},{"filename":"/home/airflow/.local/lib/python3.12/site-packages/airflow/sdk/bases/operator.py","lineno":397,"name":"wrapper"},{"filename":"/home/airflow/.local/lib/python3.12/site-packages/airflow/providers/standard/operators/python.py","lineno":217,"name":"execute"},{"filename":"/home/airflow/.local/lib/python3.12/site-packages/airflow/providers/standard/operators/python.py","lineno":240,"name":"execute_callable"},{"filename":"/home/airflow/.local/lib/python3.12/site-packages/airflow/sdk/execution_time/callback_runner.py","lineno":81,"name":"run"},{"filename":"/opt/airflow/dags/etl_dag.py","lineno":8,"name":"run_etl_script"},{"filename":"/usr/local/lib/python3.12/subprocess.py","lineno":571,"name":"run"}],"is_group":false,"exceptions":[]}]}
{"timestamp":"2025-08-05T00:38:11.396403Z","level":"info","event":"Task instance in failure state","chan":"stdout","logger":"task"}
{"timestamp":"2025-08-05T00:38:11.398213Z","level":"info","event":"Task start","chan":"stdout","logger":"task"}
{"timestamp":"2025-08-05T00:38:11.402340Z","level":"info","event":"Task:<Task(PythonOperator): run_python_etl>","chan":"stdout","logger":"task"}
{"timestamp":"2025-08-05T00:38:11.403996Z","level":"info","event":"Failure caused by Command '['python', 'python/app.py']' returned non-zero exit status 2.","chan":"stdout","logger":"task"}
